<?xml version="1.0"?>
<robot name="wheel" xmlns:xacro="http://www.ros.org/wiki/xacro">
    <xacro:macro name="wheel" params="prefix angle *joint_origin">
      <link name="${prefix}_wheel_link">
          <visual>
              <geometry>
                  <mesh filename="package://minesweeper_description/meshes/wheel.STL"/>
              </geometry>
              <origin xyz="0.0 0.0 0.0" rpy="0 0 ${radians(angle)}"/>
              <material name="black">
                  <color rgba="0.05 0.05 0.05 1.0"/>
              </material>
          </visual>
          <collision>
              <geometry>
                  <cylinder radius="0.15955" length="0.100"/>
              </geometry>
              <origin xyz="0.0 ${0.125*cos(radians(angle))} 0.0" rpy="0 ${radians(90)} ${radians(90)}"/>
          </collision>
          <inertial>
            <mass value="2.8" />
            <inertia  ixx="0.02467" ixy="0" ixz="0" iyy="0.04411" iyz="0" izz="0.02467" />
          </inertial>
      </link>
      <gazebo reference="${prefix}_wheel_link">
        <visual name="{prefix}_wheel_visual">
            <material>
                <diffuse>0.05 0.05 0.05 1.0</diffuse>
                <specular>0.05 0.05 0.05 1.0</specular>
                <ambient>0.05 0.05 0.05 1.0</ambient>
            </material>
        </visual>
      </gazebo>
      <gazebo reference="${prefix}_wheel_link">
  			<mu1 value="1.0"/>
  			<mu2 value="1.0"/>
  			<kp value="10000000.0" />
  			<kd value="1.0" />
  			<fdir1 value="1 0 0"/>
  		</gazebo>
      <joint name="${prefix}_wheel" type="continuous">
          <parent link="base_link"/>
          <child link="${prefix}_wheel_link"/>
          <axis xyz="0 1 0"/>
          <xacro:insert_block name="joint_origin"/>
      </joint>
      <transmission name="${prefix}_wheel_transmission">
        <type>transmission_interface/SimpleTransmission</type>
        <joint name="${prefix}_wheel">
            <hardwareInterface>VelocityJointInterface</hardwareInterface>
        </joint>
        <actuator name="${prefix}_wheel_actuator">
            <mechanicalReduction>1</mechanicalReduction>
        </actuator>
      </transmission>
    </xacro:macro>
</robot>
